OrderBookSim/OrderBookSim/Outputs/Log1361622098.txt
0--INFO	Added rule
0--INFO	Added rule
0--INFO	Added rule
0--INFO	Added rule
1266--INFO	Enqueued order: Price: 2147483647.00, Volume: 294, Type: BUY, Market Order: 1, Participant: 49, Stock:[ID: 0, Symbol: GOOG], Time: 1266, OrderNumber: 0
1275--INFO	Enqueued order: Price: 2147483647.00, Volume: 749, Type: BUY, Market Order: 1, Participant: 107, Stock:[ID: 0, Symbol: GOOG], Time: 1275, OrderNumber: 1
1279--INFO	Enqueued order: Price: 2147483647.00, Volume: 234, Type: BUY, Market Order: 1, Participant: 106, Stock:[ID: 0, Symbol: GOOG], Time: 1279, OrderNumber: 2
1292--INFO	Enqueued order: Price: 100.01, Volume: 953, Type: SELL, Market Order: 0, Participant: 47, Stock:[ID: 0, Symbol: GOOG], Time: 1292, OrderNumber: 3
1293--INFO	Last Price Set:100.01
1293--INFO	Notified Traders of trade1293---Trade ID: 0, Price: 100.01, Volume: 294 between ID:[49] and ID:[47]
1293--INFO	Last Price Set:100.01
1293--INFO	Notified Traders of trade1293---Trade ID: 1, Price: 100.01, Volume: 659 between ID:[107] and ID:[47]
1310--INFO	Enqueued order: Price: 0.00, Volume: 894, Type: SELL, Market Order: 1, Participant: 30, Stock:[ID: 0, Symbol: GOOG], Time: 1310, OrderNumber: 4
1311--INFO	Last Price Set:100.01
1311--INFO	Notified Traders of trade1311---Trade ID: 2, Price: 100.01, Volume: 749 between ID:[107] and ID:[30]
1311--INFO	Last Price Set:100.01
1311--INFO	Notified Traders of trade1311---Trade ID: 3, Price: 100.01, Volume: 145 between ID:[106] and ID:[30]
1328--INFO	Enqueued order: Price: 0.00, Volume: 371, Type: SELL, Market Order: 1, Participant: 82, Stock:[ID: 0, Symbol: GOOG], Time: 1328, OrderNumber: 5
1329--INFO	Last Price Set:100.01
1329--INFO	Notified Traders of trade1329---Trade ID: 4, Price: 100.01, Volume: 234 between ID:[106] and ID:[82]
1347--INFO	Enqueued order: Price: 100.10, Volume: 89, Type: SELL, Market Order: 0, Participant: 45, Stock:[ID: 0, Symbol: GOOG], Time: 1347, OrderNumber: 6
1355--INFO	Enqueued order: Price: 2147483647.00, Volume: 47, Type: BUY, Market Order: 1, Participant: 25, Stock:[ID: 0, Symbol: GOOG], Time: 1355, OrderNumber: 7
1356--INFO	Last Price Set:100.01
1356--INFO	Notified Traders of trade1356---Trade ID: 5, Price: 100.01, Volume: 47 between ID:[25] and ID:[82]
1369--INFO	Enqueued order: Price: 0.00, Volume: 977, Type: SELL, Market Order: 1, Participant: 6, Stock:[ID: 0, Symbol: GOOG], Time: 1369, OrderNumber: 8
1397--INFO	Enqueued order: Price: 0.00, Volume: 354, Type: SELL, Market Order: 1, Participant: 42, Stock:[ID: 0, Symbol: GOOG], Time: 1397, OrderNumber: 9
1397--INFO	Enqueued order: Price: 0.00, Volume: 665, Type: SELL, Market Order: 1, Participant: 70, Stock:[ID: 0, Symbol: GOOG], Time: 1397, OrderNumber: 10
1423--INFO	Enqueued order: Price: 2147483647.00, Volume: 941, Type: BUY, Market Order: 1, Participant: 61, Stock:[ID: 0, Symbol: GOOG], Time: 1423, OrderNumber: 11
1424--INFO	Last Price Set:100.01
1424--INFO	Notified Traders of trade1424---Trade ID: 6, Price: 100.01, Volume: 137 between ID:[61] and ID:[82]
1424--INFO	Last Price Set:100.01
1424--INFO	Notified Traders of trade1424---Trade ID: 7, Price: 100.01, Volume: 804 between ID:[61] and ID:[6]
1428--INFO	Enqueued order: Price: 2147483647.00, Volume: 42, Type: BUY, Market Order: 1, Participant: 7, Stock:[ID: 0, Symbol: GOOG], Time: 1428, OrderNumber: 12
1429--INFO	Last Price Set:100.01
1429--INFO	Notified Traders of trade1429---Trade ID: 8, Price: 100.01, Volume: 42 between ID:[7] and ID:[6]
1452--INFO	Enqueued order: Price: 2147483647.00, Volume: 314, Type: BUY, Market Order: 1, Participant: 18, Stock:[ID: 0, Symbol: GOOG], Time: 1452, OrderNumber: 13
1453--INFO	Last Price Set:100.01
1453--INFO	Notified Traders of trade1453---Trade ID: 9, Price: 100.01, Volume: 314 between ID:[18] and ID:[6]
1490--INFO	Enqueued order: Price: 0.00, Volume: 2, Type: SELL, Market Order: 1, Participant: 34, Stock:[ID: 0, Symbol: GOOG], Time: 1490, OrderNumber: 14
1545--INFO	Enqueued order: Price: 2147483647.00, Volume: 502, Type: BUY, Market Order: 1, Participant: 93, Stock:[ID: 0, Symbol: GOOG], Time: 1545, OrderNumber: 15
1546--INFO	Last Price Set:100.01
1546--INFO	Notified Traders of trade1546---Trade ID: 10, Price: 100.01, Volume: 502 between ID:[93] and ID:[6]
1570--INFO	Enqueued order: Price: 0.00, Volume: 316, Type: SELL, Market Order: 1, Participant: 124, Stock:[ID: 0, Symbol: GOOG], Time: 1570, OrderNumber: 16
1580--INFO	Enqueued order: Price: 0.00, Volume: 558, Type: SELL, Market Order: 1, Participant: 4, Stock:[ID: 0, Symbol: GOOG], Time: 1580, OrderNumber: 17
1598--INFO	Enqueued order: Price: 99.96, Volume: 98, Type: BUY, Market Order: 0, Participant: 54, Stock:[ID: 0, Symbol: GOOG], Time: 1598, OrderNumber: 18
1599--INFO	Last Price Set:99.96
1599--INFO	Notified Traders of trade1599---Trade ID: 11, Price: 99.96, Volume: 98 between ID:[54] and ID:[6]
1619--INFO	Enqueued order: Price: 2147483647.00, Volume: 697, Type: BUY, Market Order: 1, Participant: 11, Stock:[ID: 0, Symbol: GOOG], Time: 1619, OrderNumber: 19
1620--INFO	Last Price Set:99.96
1620--INFO	Notified Traders of trade1620---Trade ID: 12, Price: 99.96, Volume: 697 between ID:[11] and ID:[6]
1641--INFO	Enqueued order: Price: 2147483647.00, Volume: 615, Type: BUY, Market Order: 1, Participant: 32, Stock:[ID: 0, Symbol: GOOG], Time: 1641, OrderNumber: 20
1642--INFO	Last Price Set:99.96
1642--INFO	Notified Traders of trade1642---Trade ID: 13, Price: 99.96, Volume: 615 between ID:[32] and ID:[6]
1682--INFO	Enqueued order: Price: 0.00, Volume: 109, Type: SELL, Market Order: 1, Participant: 14, Stock:[ID: 0, Symbol: GOOG], Time: 1682, OrderNumber: 21
1686--INFO	Enqueued order: Price: 2147483647.00, Volume: 609, Type: BUY, Market Order: 1, Participant: 109, Stock:[ID: 0, Symbol: GOOG], Time: 1686, OrderNumber: 22
1687--INFO	Last Price Set:99.96
1687--INFO	Notified Traders of trade1687---Trade ID: 14, Price: 99.96, Volume: 609 between ID:[109] and ID:[6]
1744--INFO	Enqueued order: Price: 0.00, Volume: 786, Type: SELL, Market Order: 1, Participant: 79, Stock:[ID: 0, Symbol: GOOG], Time: 1744, OrderNumber: 23
1750--INFO	Enqueued order: Price: 2147483647.00, Volume: 379, Type: BUY, Market Order: 1, Participant: 53, Stock:[ID: 0, Symbol: GOOG], Time: 1750, OrderNumber: 24
1751--INFO	Last Price Set:99.96
1751--INFO	Notified Traders of trade1751---Trade ID: 15, Price: 99.96, Volume: 379 between ID:[53] and ID:[6]
1791--INFO	Enqueued order: Price: 0.00, Volume: 940, Type: SELL, Market Order: 1, Participant: 81, Stock:[ID: 0, Symbol: GOOG], Time: 1791, OrderNumber: 25
1825--INFO	Enqueued order: Price: 99.98, Volume: 489, Type: SELL, Market Order: 0, Participant: 50, Stock:[ID: 0, Symbol: GOOG], Time: 1825, OrderNumber: 26
1843--INFO	Enqueued order: Price: 0.00, Volume: 329, Type: SELL, Market Order: 1, Participant: 16, Stock:[ID: 0, Symbol: GOOG], Time: 1843, OrderNumber: 27
1851--INFO	Enqueued order: Price: 2147483647.00, Volume: 657, Type: BUY, Market Order: 1, Participant: 115, Stock:[ID: 0, Symbol: GOOG], Time: 1851, OrderNumber: 28
1852--INFO	Last Price Set:99.96
1852--INFO	Notified Traders of trade1852---Trade ID: 16, Price: 99.96, Volume: 657 between ID:[115] and ID:[6]
1861--INFO	Enqueued order: Price: 0.00, Volume: 945, Type: SELL, Market Order: 1, Participant: 96, Stock:[ID: 0, Symbol: GOOG], Time: 1861, OrderNumber: 29
1892--INFO	Enqueued order: Price: 0.00, Volume: 798, Type: SELL, Market Order: 1, Participant: 19, Stock:[ID: 0, Symbol: GOOG], Time: 1892, OrderNumber: 30
1912--INFO	Enqueued order: Price: 0.00, Volume: 868, Type: SELL, Market Order: 1, Participant: 113, Stock:[ID: 0, Symbol: GOOG], Time: 1912, OrderNumber: 31
1912--INFO	Enqueued order: Price: 0.00, Volume: 868, Type: SELL, Market Order: 1, Participant: 114, Stock:[ID: 0, Symbol: GOOG], Time: 1912, OrderNumber: 32
1922--INFO	Enqueued order: Price: 99.96, Volume: 910, Type: BUY, Market Order: 0, Participant: 35, Stock:[ID: 0, Symbol: GOOG], Time: 1922, OrderNumber: 33
1923--INFO	Last Price Set:99.96
1923--INFO	Notified Traders of trade1923---Trade ID: 17, Price: 99.96, Volume: 910 between ID:[35] and ID:[6]
